<?xml version="1.0" encoding="UTF-8"?>
<robot name="g1_minimal_with_leg_hand_collision">
  <joint name="imu_joint" type="fixed">
    <origin xyz="-0.0039635 0. 0.044 " rpy="-0. 0.0000001 -0.0000001"/>
    <parent link="g1_29dof_with_hand_rev_1_0"/>
    <child link="g1_29dof_with_hand_rev_1_0_pelvis"/>
  </joint>
  <joint name="left_ankle_pitch_joint" type="revolute">
    <origin xyz="-0. -0.0000944 -0.30001 " rpy="0. -0. 0.0000001"/>
    <parent link="g1_29dof_with_hand_rev_1_0_left_knee_link"/>
    <child link="g1_29dof_with_hand_rev_1_0_left_ankle_pitch_link"/>
    <axis xyz="0. 1. 0."/>
    <limit lower="-0.87267" upper="0.5235999" effort="50." velocity="37.0000001"/>
  </joint>
  <joint name="left_ankle_roll_back_joint" type="fixed">
    <origin xyz="-0. -0. 0." rpy="0. -0. 0."/>
    <parent link="g1_29dof_with_hand_rev_1_0_left_ankle_roll_link"/>
    <child link="left_ankle_roll_back_link"/>
  </joint>
  <joint name="left_ankle_roll_front_joint" type="fixed">
    <origin xyz="0. -0. 0." rpy="0. -0. 0."/>
    <parent link="g1_29dof_with_hand_rev_1_0_left_ankle_roll_link"/>
    <child link="left_ankle_roll_front_link"/>
  </joint>
  <joint name="left_ankle_roll_joint" type="revolute">
    <origin xyz="0. -0. -0.017558" rpy="-0. 0. 0.0000001"/>
    <parent link="g1_29dof_with_hand_rev_1_0_left_ankle_pitch_link"/>
    <child link="g1_29dof_with_hand_rev_1_0_left_ankle_roll_link"/>
    <axis xyz="1. 0. 0."/>
    <limit lower="-0.2618" upper="0.2618" effort="50." velocity="37.0000001"/>
  </joint>
  <joint name="left_ankle_roll_mid_joint" type="fixed">
    <origin xyz="-0. -0. 0." rpy="0. -0. 0."/>
    <parent link="g1_29dof_with_hand_rev_1_0_left_ankle_roll_link"/>
    <child link="left_ankle_roll_mid_link"/>
  </joint>
  <joint name="left_elbow_joint" type="revolute">
    <origin xyz="0.015783 0. -0.0805179" rpy="-0. 0.0000001 -0. "/>
    <parent link="g1_29dof_with_hand_rev_1_0_left_shoulder_yaw_link"/>
    <child link="g1_29dof_with_hand_rev_1_0_left_elbow_link"/>
    <axis xyz="0. 1. 0."/>
    <limit lower="-1.0471999" upper="2.0943998" effort="25." velocity="37.0000001"/>
  </joint>
  
  <joint name="L_base_link_joint" type="fixed">
    <origin xyz="0.0415 0 0" rpy="0 0 1.5707963267948966192313216916398"/>
    <parent link="g1_29dof_with_hand_rev_1_0_left_wrist_yaw_link"/>
    <child link="L_hand_base_link"/>
  </joint>

  <link name="L_hand_base_link"/>

  <joint name="L_thumb_proximal_yaw_joint" type="revolute">
    <origin xyz="-0.01696 -0.0691 0.02045" rpy="1.5708 -1.5708 0"/>
    <parent link="L_hand_base_link"/>
    <child link="L_thumb_proximal_base"/>
    <axis xyz="0 0 1"/>
    <limit lower="-0.1" upper="1.3" effort="1" velocity="0.5"/>
  </joint>

  <link name="L_thumb_proximal_base"/>

  <joint name="L_thumb_proximal_pitch_joint" type="revolute">
    <origin xyz="0.0099867 0.0098242 -0.0089" rpy="-1.5708 0 0.16939"/>
    <parent link="L_thumb_proximal_base"/>
    <child link="L_thumb_proximal"/>
    <axis xyz="0 0 -1"/>
    <limit lower="-0.1" upper="0.6" effort="1" velocity="0.5"/>
  </joint>

  <link name="L_thumb_proximal"/>

  <joint name="L_thumb_intermediate_joint" type="revolute">
    <origin xyz="0.04407 -0.034553 -0.0008" rpy="0 0 0"/>
    <parent link="L_thumb_proximal"/>
    <child link="L_thumb_intermediate"/>
    <axis xyz="0 0 -1"/>
    <limit lower="0" upper="0.8" effort="1" velocity="0.5"/>
    <mimic joint="L_thumb_proximal_pitch_joint" multiplier="1.6" offset="0"/>
  </joint>

  <link name="L_thumb_intermediate"/>

  <joint name="L_thumb_distal_joint" type="revolute">
    <origin xyz="0.020248 -0.010156 -0.0012" rpy="0 0 0"/>
    <parent link="L_thumb_intermediate"/>
    <child link="L_thumb_distal"/>
    <axis xyz="0 0 -1"/>
    <limit lower="0" upper="1.2" effort="1" velocity="0.5"/>
    <mimic joint="L_thumb_proximal_pitch_joint" multiplier="2.4" offset="0"/>
  </joint>

  <link name="L_thumb_distal"/>

  <joint name="L_index_proximal_joint" type="revolute">
    <origin xyz="0.00028533 -0.13653 0.032268" rpy="-0.034907 0 0"/>
    <parent link="L_hand_base_link"/>
    <child link="L_index_proximal"/>
    <axis xyz="0 0 -1"/>
    <limit lower="0" upper="1.7" effort="1" velocity="0.5"/>
  </joint>

  <link name="L_index_proximal"/>

  <joint name="L_index_intermediate_joint" type="revolute">
    <origin xyz="-0.0024229 -0.032041 -0.001" rpy="0 0 0"/>
    <parent link="L_index_proximal"/>
    <child link="L_index_intermediate"/>
    <axis xyz="0 0 -1"/>
    <limit lower="0" upper="1.7" effort="1" velocity="0.5"/>
    <mimic joint="L_index_proximal_joint" multiplier="1" offset="0"/>
  </joint>

  <link name="L_index_intermediate"/>

  <joint name="L_middle_proximal_joint" type="revolute">
    <origin xyz="0.00028533 -0.1371 0.01295" rpy="0 0 0"/>
    <parent link="L_hand_base_link"/>
    <child link="L_middle_proximal"/>
    <axis xyz="0 0 -1"/>
    <limit lower="0" upper="1.7" effort="1" velocity="0.5"/>
  </joint>

  <link name="L_middle_proximal"/>

  <joint name="L_middle_intermediate_joint" type="revolute">
    <origin xyz="-0.0024229 -0.032041 -0.001" rpy="0 0 0"/>
    <parent link="L_middle_proximal"/>
    <child link="L_middle_intermediate"/>
    <axis xyz="0 0 -1"/>
    <limit lower="0" upper="1.7" effort="1" velocity="0.5"/>
    <mimic joint="L_middle_proximal_joint" multiplier="1" offset="0"/>
  </joint>

  <link name="L_middle_intermediate"/>

  <joint name="L_ring_proximal_joint" type="revolute">
    <origin xyz="0.00028533 -0.13691 -0.0062872" rpy="0.05236 0 0"/>
    <parent link="L_hand_base_link"/>
    <child link="L_ring_proximal"/>
    <axis xyz="0 0 -1"/>
    <limit lower="0" upper="1.7" effort="1" velocity="0.5"/>
  </joint>

  <link name="L_ring_proximal"/>

  <joint name="L_ring_intermediate_joint" type="revolute">
    <origin xyz="-0.0024229 -0.032041 -0.001" rpy="0 0 0"/>
    <parent link="L_ring_proximal"/>
    <child link="L_ring_intermediate"/>
    <axis xyz="0 0 -1"/>
    <limit lower="0" upper="1.7" effort="1" velocity="0.5"/>
    <mimic joint="L_ring_proximal_joint" multiplier="1" offset="0"/>
  </joint>

  <link name="L_ring_intermediate"/>

  <joint name="L_pinky_proximal_joint" type="revolute">
    <origin xyz="0.00028533 -0.13571 -0.025488" rpy="0.10472 0 0"/>
    <parent link="L_hand_base_link"/>
    <child link="L_pinky_proximal"/>
    <axis xyz="0 0 -1"/>
    <limit lower="0" upper="1.7" effort="1" velocity="0.5"/>
  </joint>

  <link name="L_pinky_proximal"/>

  <joint name="L_pinky_intermediate_joint" type="revolute">
    <origin xyz="-0.0024229 -0.032041 -0.001" rpy="0 0 0"/>
    <parent link="L_pinky_proximal"/>
    <child link="L_pinky_intermediate"/>
    <axis xyz="0 0 -1"/>
    <limit lower="0" upper="1.7" effort="1" velocity="0.5"/>
    <mimic joint="L_pinky_proximal_joint" multiplier="1" offset="0"/>
  </joint>


  <link name="L_pinky_intermediate"/>









  <joint name="left_hip_pitch_joint" type="revolute">
    <origin xyz="0. 0.064452 -0.1027 " rpy="0. 0. 0."/>
    <parent link="g1_29dof_with_hand_rev_1_0_pelvis"/>
    <child link="g1_29dof_with_hand_rev_1_0_left_hip_pitch_link"/>
    <axis xyz="0. 1. 0."/>
    <limit lower="-2.5306997" upper="2.8797999" effort="88." velocity="31.9999982"/>
  </joint>
  <joint name="left_hip_roll_joint" type="revolute">
    <origin xyz="-0. 0.052 -0.030465" rpy="0. -0.1749 0.0000001"/>
    <parent link="g1_29dof_with_hand_rev_1_0_left_hip_pitch_link"/>
    <child link="g1_29dof_with_hand_rev_1_0_left_hip_roll_link"/>
    <axis xyz="1. 0. 0."/>
    <limit lower="-0.5235999" upper="2.9670997" effort="139." velocity="19.9999989"/>
  </joint>
  <joint name="left_hip_yaw_joint" type="revolute">
    <origin xyz="0.025001 -0. -0.12412 " rpy="0. 0. 0."/>
    <parent link="g1_29dof_with_hand_rev_1_0_left_hip_roll_link"/>
    <child link="g1_29dof_with_hand_rev_1_0_left_hip_yaw_link"/>
    <axis xyz="0. 0. 1."/>
    <limit lower="-2.7576" upper="2.7576" effort="88." velocity="31.9999982"/>
  </joint>
  <joint name="left_knee_joint" type="revolute">
    <origin xyz="-0.078273 0.0021489 -0.17734 " rpy="0. 0.1749 0. "/>
    <parent link="g1_29dof_with_hand_rev_1_0_left_hip_yaw_link"/>
    <child link="g1_29dof_with_hand_rev_1_0_left_knee_link"/>
    <axis xyz="0. 1. 0."/>
    <limit lower="-0.087267" upper="2.8797999" effort="139." velocity="19.9999989"/>
  </joint>
  <joint name="left_shoulder_pitch_joint" type="revolute">
    <origin xyz="0.0039563 0.10022 0.24778 " rpy="0.27931 0.0000549 -0.0001916"/>
    <parent link="torso_link"/>
    <child link="g1_29dof_with_hand_rev_1_0_left_shoulder_pitch_link"/>
    <axis xyz="0. 1. 0."/>
    <limit lower="-3.0891998" upper="2.6703998" effort="25." velocity="37.0000001"/>
  </joint>
  <joint name="left_shoulder_roll_joint" type="revolute">
    <origin xyz="0. 0.0379999 -0.013831 " rpy="-0.2792501 0. 0. "/>
    <parent link="g1_29dof_with_hand_rev_1_0_left_shoulder_pitch_link"/>
    <child link="g1_29dof_with_hand_rev_1_0_left_shoulder_roll_link"/>
    <axis xyz="1. 0. 0."/>
    <limit lower="-1.5882" upper="2.2514998" effort="25." velocity="37.0000001"/>
  </joint>
  <joint name="left_shoulder_yaw_joint" type="revolute">
    <origin xyz="0. 0.00624 -0.1032 " rpy="0.0000001 0. 0. "/>
    <parent link="g1_29dof_with_hand_rev_1_0_left_shoulder_roll_link"/>
    <child link="g1_29dof_with_hand_rev_1_0_left_shoulder_yaw_link"/>
    <axis xyz="0. 0. 1."/>
    <limit lower="-2.618" upper="2.618" effort="25." velocity="37.0000001"/>
  </joint>
  <joint name="left_wrist_pitch_joint" type="revolute">
    <origin xyz="0.038 0. -0. " rpy="-0. 0. 0."/>
    <parent link="g1_29dof_with_hand_rev_1_0_left_wrist_roll_link"/>
    <child link="g1_29dof_with_hand_rev_1_0_left_wrist_pitch_link"/>
    <axis xyz="0. 1. 0."/>
    <limit lower="-1.6144296" upper="1.6144296" effort="5." velocity="21.9999988"/>
  </joint>
  <joint name="left_wrist_roll_joint" type="revolute">
    <origin xyz="0.1 0.0018879 -0.01 " rpy="0. 0. -0."/>
    <parent link="g1_29dof_with_hand_rev_1_0_left_elbow_link"/>
    <child link="g1_29dof_with_hand_rev_1_0_left_wrist_roll_link"/>
    <axis xyz="1. 0. 0."/>
    <limit lower="-1.9722219" upper="1.9722219" effort="25." velocity="37.0000001"/>
  </joint>
  <joint name="left_wrist_yaw_joint" type="revolute">
    <origin xyz="0.046 0. -0. " rpy="0.0000001 -0. 0.0000002"/>
    <parent link="g1_29dof_with_hand_rev_1_0_left_wrist_pitch_link"/>
    <child link="g1_29dof_with_hand_rev_1_0_left_wrist_yaw_link"/>
    <axis xyz="0. 0. 1."/>
    <limit lower="-1.6144296" upper="1.6144296" effort="5." velocity="21.9999988"/>
  </joint>
  <joint name="right_ankle_pitch_joint" type="revolute">
    <origin xyz="-0. 0.0000945 -0.30001 " rpy="-0. -0. -0."/>
    <parent link="g1_29dof_with_hand_rev_1_0_right_knee_link"/>
    <child link="g1_29dof_with_hand_rev_1_0_right_ankle_pitch_link"/>
    <axis xyz="0. 1. 0."/>
    <limit lower="-0.87267" upper="0.5235999" effort="50." velocity="37.0000001"/>
  </joint>
  <joint name="right_ankle_roll_back_joint" type="fixed">
    <origin xyz="-0. 0. 0." rpy="-0. -0. -0."/>
    <parent link="g1_29dof_with_hand_rev_1_0_right_ankle_roll_link"/>
    <child link="right_ankle_roll_back_link"/>
  </joint>
  <joint name="right_ankle_roll_front_joint" type="fixed">
    <origin xyz="-0. 0. 0." rpy="-0. -0. -0."/>
    <parent link="g1_29dof_with_hand_rev_1_0_right_ankle_roll_link"/>
    <child link="right_ankle_roll_front_link"/>
  </joint>
  <joint name="right_ankle_roll_joint" type="revolute">
    <origin xyz="0. -0. -0.0175579" rpy="-0. -0. -0."/>
    <parent link="g1_29dof_with_hand_rev_1_0_right_ankle_pitch_link"/>
    <child link="g1_29dof_with_hand_rev_1_0_right_ankle_roll_link"/>
    <axis xyz="1. 0. 0."/>
    <limit lower="-0.2618" upper="0.2618" effort="50." velocity="37.0000001"/>
  </joint>
  <joint name="right_ankle_roll_mid_joint" type="fixed">
    <origin xyz="-0. 0. 0." rpy="-0. -0. -0."/>
    <parent link="g1_29dof_with_hand_rev_1_0_right_ankle_roll_link"/>
    <child link="right_ankle_roll_mid_link"/>
  </joint>
  <joint name="right_elbow_joint" type="revolute">
    <origin xyz="0.015783 -0. -0.0805179" rpy="0. 0.0000001 0. "/>
    <parent link="g1_29dof_with_hand_rev_1_0_right_shoulder_yaw_link"/>
    <child link="g1_29dof_with_hand_rev_1_0_right_elbow_link"/>
    <axis xyz="0. 1. 0."/>
    <limit lower="-1.0471999" upper="2.0943998" effort="25." velocity="37.0000001"/>
  </joint>

  <joint name="R_base_link_joint" type="fixed">
    <origin xyz="0.0415 0 0" rpy="3.1415926535897932384626433832795 0 -1.5707963267948966192313216916398"/>
    <parent link="g1_29dof_with_hand_rev_1_0_right_wrist_yaw_link"/>
    <child link="R_hand_base_link"/>
  </joint>

  <link name="R_hand_base_link"/>

  <link name="R_thumb_proximal_base"/>

  <joint name="R_thumb_proximal_yaw_joint" type="revolute">
    <origin xyz="-0.01696 -0.0691 -0.02045" rpy="1.5708 -1.5708 0"/>
    <parent link="R_hand_base_link"/>
    <child link="R_thumb_proximal_base"/>
    <axis xyz="0 0 -1"/>
    <limit lower="-0.1" upper="1.3" effort="1" velocity="0.5"/>
  </joint>

  <link name="R_thumb_proximal"/>

  <joint name="R_thumb_proximal_pitch_joint" type="revolute">
    <origin xyz="-0.0088099 0.010892 -0.00925" rpy="1.5708 0 2.8587"/>
    <parent link="R_thumb_proximal_base"/>
    <child link="R_thumb_proximal"/>
    <axis xyz="0 0 1"/>
    <limit lower="-0.1" upper="0.6" effort="1" velocity="0.5"/>
  </joint>

  <link name="R_thumb_intermediate"/>

  <joint name="R_thumb_intermediate_joint" type="revolute">
    <origin xyz="0.04407 0.034553 -0.0008" rpy="0 0 0"/>
    <parent link="R_thumb_proximal"/>
    <child link="R_thumb_intermediate"/>
    <axis xyz="0 0 1"/>
    <limit lower="0" upper="0.8" effort="1" velocity="0.5"/>
    <mimic joint="R_thumb_proximal_pitch_joint" multiplier="1.6" offset="0"/>
  </joint>

  <link name="R_thumb_distal"/>

  <joint name="R_thumb_distal_joint" type="revolute">
    <origin xyz="0.020248 0.010156 -0.0012" rpy="0 0 0"/>
    <parent link="R_thumb_intermediate"/>
    <child link="R_thumb_distal"/>
    <axis xyz="0 0 1"/>
    <limit lower="0" upper="1.2" effort="1" velocity="0.5"/>
    <mimic joint="R_thumb_proximal_pitch_joint" multiplier="2.4" offset="0"/>
  </joint>

  <link name="R_index_proximal"/>


  <joint name="R_index_proximal_joint" type="revolute">
    <origin xyz="0.00028533 -0.13653 -0.032268" rpy="-3.1067 0 0"/>
    <parent link="R_hand_base_link"/>
    <child link="R_index_proximal"/>
    <axis xyz="0 0 1"/>
    <limit lower="0" upper="1.7" effort="1" velocity="0.5"/>
  </joint>

  <link name="R_index_intermediate"/>

  <joint name="R_index_intermediate_joint" type="revolute">
    <origin xyz="-0.0026138 0.032026 -0.001" rpy="0 0 0"/>
    <parent link="R_index_proximal"/>
    <child link="R_index_intermediate"/>
    <axis xyz="0 0 1"/>
    <limit lower="0" upper="1.7" effort="1" velocity="0.5"/>
    <mimic joint="R_index_proximal_joint" multiplier="1" offset="0"/>
  </joint>

  <link name="R_middle_proximal"/>

  <joint name="R_middle_proximal_joint" type="revolute">
    <origin xyz="0.00028533 -0.1371 -0.01295" rpy="-3.1416 0 0"/>
    <parent link="R_hand_base_link"/>
    <child link="R_middle_proximal"/>
    <axis xyz="0 0 1"/>
    <limit lower="0" upper="1.7" effort="1" velocity="0.5"/>
  </joint>

  <link name="R_middle_intermediate"/>


  <joint name="R_middle_intermediate_joint" type="revolute">
    <origin xyz="-0.0024229 0.032041 -0.001" rpy="0 0 0"/>
    <parent link="R_middle_proximal"/>
    <child link="R_middle_intermediate"/>
    <axis xyz="0 0 1"/>
    <limit lower="0" upper="1.7" effort="1" velocity="0.5"/>
    <mimic joint="R_middle_proximal_joint" multiplier="1" offset="0"/>
  </joint>

  <link name="R_ring_proximal"/>

  <joint name="R_ring_proximal_joint" type="revolute">
    <origin xyz="0.00028533 -0.13691 0.0062872" rpy="3.0892 0 0"/>
    <parent link="R_hand_base_link"/>
    <child link="R_ring_proximal"/>
    <axis xyz="0 0 1"/>
    <limit lower="0" upper="1.7" effort="1" velocity="0.5"/>
  </joint>

  <link name="R_ring_intermediate"/>


  <joint name="R_ring_intermediate_joint" type="revolute">
    <origin xyz="-0.0024229 0.032041 -0.001" rpy="0 0 0"/>
    <parent link="R_ring_proximal"/>
    <child link="R_ring_intermediate"/>
    <axis xyz="0 0 1"/>
    <limit lower="0" upper="1.7" effort="1" velocity="0.5"/>
    <mimic joint="R_ring_proximal_joint" multiplier="1" offset="0"/>
  </joint>

  <link name="R_pinky_proximal"/>


  <joint name="R_pinky_proximal_joint" type="revolute">
    <origin xyz="0.00028533 -0.13571 0.025488" rpy="3.0369 0 0"/>
    <parent link="R_hand_base_link"/>
    <child link="R_pinky_proximal"/>
    <axis xyz="0 0 1"/>
    <limit lower="0" upper="1.7" effort="1" velocity="0.5"/>
  </joint>

  <link name="R_pinky_intermediate"/>

  <joint name="R_pinky_intermediate_joint" type="revolute">
    <origin xyz="-0.0024229 0.032041 -0.001" rpy="0 0 0"/>
    <parent link="R_pinky_proximal"/>
    <child link="R_pinky_intermediate"/>
    <axis xyz="0 0 1"/>
    <limit lower="0" upper="1.7" effort="1" velocity="0.5"/>
    <mimic joint="R_pinky_proximal_joint" multiplier="1" offset="0"/>
  </joint>








  <joint name="right_hip_pitch_joint" type="revolute">
    <origin xyz="0. -0.064452 -0.1027 " rpy="0. 0. 0."/>
    <parent link="g1_29dof_with_hand_rev_1_0_pelvis"/>
    <child link="g1_29dof_with_hand_rev_1_0_right_hip_pitch_link"/>
    <axis xyz="0. 1. 0."/>
    <limit lower="-2.5306997" upper="2.8797999" effort="88." velocity="31.9999982"/>
  </joint>
  <joint name="right_hip_roll_joint" type="revolute">
    <origin xyz="-0. -0.052 -0.030465" rpy="-0. -0.1749 -0.0000001"/>
    <parent link="g1_29dof_with_hand_rev_1_0_right_hip_pitch_link"/>
    <child link="g1_29dof_with_hand_rev_1_0_right_hip_roll_link"/>
    <axis xyz="1. 0. 0."/>
    <limit lower="-2.9670997" upper="0.5235999" effort="139." velocity="19.9999989"/>
  </joint>
  <joint name="right_hip_yaw_joint" type="revolute">
    <origin xyz="0.025001 0. -0.12412 " rpy="-0. 0. 0."/>
    <parent link="g1_29dof_with_hand_rev_1_0_right_hip_roll_link"/>
    <child link="g1_29dof_with_hand_rev_1_0_right_hip_yaw_link"/>
    <axis xyz="0. 0. 1."/>
    <limit lower="-2.7576" upper="2.7576" effort="88." velocity="31.9999982"/>
  </joint>
  <joint name="right_knee_joint" type="revolute">
    <origin xyz="-0.078273 -0.0021489 -0.17734 " rpy="-0. 0.1749 -0. "/>
    <parent link="g1_29dof_with_hand_rev_1_0_right_hip_yaw_link"/>
    <child link="g1_29dof_with_hand_rev_1_0_right_knee_link"/>
    <axis xyz="0. 1. 0."/>
    <limit lower="-0.087267" upper="2.8797999" effort="139." velocity="19.9999989"/>
  </joint>
  <joint name="right_shoulder_pitch_joint" type="revolute">
    <origin xyz="0.0039563 -0.10021 0.24778 " rpy="-0.27931 0.0000549 0.0001916"/>
    <parent link="torso_link"/>
    <child link="g1_29dof_with_hand_rev_1_0_right_shoulder_pitch_link"/>
    <axis xyz="0. 1. 0."/>
    <limit lower="-3.0891998" upper="2.6703998" effort="25." velocity="37.0000001"/>
  </joint>
  <joint name="right_shoulder_roll_joint" type="revolute">
    <origin xyz="0. -0.038 -0.013831" rpy="0.27925 -0. 0. "/>
    <parent link="g1_29dof_with_hand_rev_1_0_right_shoulder_pitch_link"/>
    <child link="g1_29dof_with_hand_rev_1_0_right_shoulder_roll_link"/>
    <axis xyz="1. 0. 0."/>
    <limit lower="-2.2514998" upper="1.5882" effort="25." velocity="37.0000001"/>
  </joint>
  <joint name="right_shoulder_yaw_joint" type="revolute">
    <origin xyz="-0. -0.00624 -0.1032 " rpy="-0. 0. -0."/>
    <parent link="g1_29dof_with_hand_rev_1_0_right_shoulder_roll_link"/>
    <child link="g1_29dof_with_hand_rev_1_0_right_shoulder_yaw_link"/>
    <axis xyz="0. 0. 1."/>
    <limit lower="-2.618" upper="2.618" effort="25." velocity="37.0000001"/>
  </joint>
  <joint name="right_wrist_pitch_joint" type="revolute">
    <origin xyz="0.038 0. -0. " rpy="-0. 0. -0."/>
    <parent link="g1_29dof_with_hand_rev_1_0_right_wrist_roll_link"/>
    <child link="g1_29dof_with_hand_rev_1_0_right_wrist_pitch_link"/>
    <axis xyz="0. 1. 0."/>
    <limit lower="-1.6144296" upper="1.6144296" effort="5." velocity="21.9999988"/>
  </joint>
  <joint name="right_wrist_roll_joint" type="revolute">
    <origin xyz="0.1 -0.0018879 -0.01 " rpy="-0. 0. -0."/>
    <parent link="g1_29dof_with_hand_rev_1_0_right_elbow_link"/>
    <child link="g1_29dof_with_hand_rev_1_0_right_wrist_roll_link"/>
    <axis xyz="1. 0. 0."/>
    <limit lower="-1.9722219" upper="1.9722219" effort="25." velocity="37.0000001"/>
  </joint>
  <joint name="right_wrist_yaw_joint" type="revolute">
    <origin xyz="0.046 -0. -0. " rpy="-0. -0. -0.0000002"/>
    <parent link="g1_29dof_with_hand_rev_1_0_right_wrist_pitch_link"/>
    <child link="g1_29dof_with_hand_rev_1_0_right_wrist_yaw_link"/>
    <axis xyz="0. 0. 1."/>
    <limit lower="-1.6144296" upper="1.6144296" effort="5." velocity="21.9999988"/>
  </joint>
  <joint name="waist_yaw_joint" type="revolute">
    <origin xyz="0. 0. 0." rpy="0. 0. 0."/>
    <parent link="g1_29dof_with_hand_rev_1_0_pelvis"/>
    <child link="waist_yaw_link"/>
    <axis xyz="0. 0. 1."/>
    <limit lower="-0.5235988" upper="0.5235988" effort="88." velocity="31.9999982"/>
  </joint>
  <joint name="waist_roll_joint" type="revolute">
    <origin xyz="-0.00396 0. 0.044" rpy="0. 0. 0."/>
    <parent link="waist_yaw_link"/>
    <child link="waist_roll_link"/>
    <axis xyz="1. 0. 0."/>
    <limit lower="-0.2617994" upper="0.2617994" effort="50." velocity="37.0000001"/>
  </joint>
  <joint name="waist_pitch_joint" type="revolute">
    <origin xyz="0. 0. 0." rpy="0. 0. 0."/>
    <parent link="waist_roll_link"/>
    <child link="torso_link"/>
    <axis xyz="0. 1. 0."/>
    <limit lower="-0.2617994" upper="0.2617994" effort="50." velocity="37.0000001"/>
  </joint>
  <link name="g1_29dof_with_hand_rev_1_0"/>
  <link name="g1_29dof_with_hand_rev_1_0_left_ankle_pitch_link"/>
  <link name="g1_29dof_with_hand_rev_1_0_left_ankle_roll_link"/>
  <link name="g1_29dof_with_hand_rev_1_0_left_elbow_link"/>

  <link name="g1_29dof_with_hand_rev_1_0_left_hip_pitch_link"/>
  <link name="g1_29dof_with_hand_rev_1_0_left_hip_roll_link"/>
  <link name="g1_29dof_with_hand_rev_1_0_left_hip_yaw_link"/>
  <link name="g1_29dof_with_hand_rev_1_0_left_knee_link"/>
  <link name="g1_29dof_with_hand_rev_1_0_left_shoulder_pitch_link"/>
  <link name="g1_29dof_with_hand_rev_1_0_left_shoulder_roll_link"/>
  <link name="g1_29dof_with_hand_rev_1_0_left_shoulder_yaw_link"/>
  <link name="g1_29dof_with_hand_rev_1_0_left_wrist_pitch_link"/>
  <link name="g1_29dof_with_hand_rev_1_0_left_wrist_roll_link"/>
  <link name="g1_29dof_with_hand_rev_1_0_left_wrist_yaw_link"/>
  <link name="g1_29dof_with_hand_rev_1_0_pelvis"/>
  <link name="g1_29dof_with_hand_rev_1_0_right_ankle_pitch_link"/>
  <link name="g1_29dof_with_hand_rev_1_0_right_ankle_roll_link"/>
  <link name="g1_29dof_with_hand_rev_1_0_right_elbow_link"/>

  <link name="g1_29dof_with_hand_rev_1_0_right_hip_pitch_link"/>
  <link name="g1_29dof_with_hand_rev_1_0_right_hip_roll_link"/>
  <link name="g1_29dof_with_hand_rev_1_0_right_hip_yaw_link"/>
  <link name="g1_29dof_with_hand_rev_1_0_right_knee_link"/>
  <link name="g1_29dof_with_hand_rev_1_0_right_shoulder_pitch_link"/>
  <link name="g1_29dof_with_hand_rev_1_0_right_shoulder_roll_link"/>
  <link name="g1_29dof_with_hand_rev_1_0_right_shoulder_yaw_link"/>
  <link name="g1_29dof_with_hand_rev_1_0_right_wrist_pitch_link"/>
  <link name="g1_29dof_with_hand_rev_1_0_right_wrist_roll_link"/>
  <link name="g1_29dof_with_hand_rev_1_0_right_wrist_yaw_link"/>
  <link name="left_ankle_roll_back_link"/>
  <link name="left_ankle_roll_front_link"/>
  <link name="left_ankle_roll_mid_link"/>
  <link name="right_ankle_roll_back_link"/>
  <link name="right_ankle_roll_front_link"/>
  <link name="right_ankle_roll_mid_link"/>
  <link name="torso_link"/>
  <link name="waist_roll_link"/>
  <link name="waist_yaw_link"/>
</robot>
